<?xml version="1.0" ?>

<robot name="basic_link">

    <link name="base_link">
        <visual>
            <origin xyz="0.0 0.0 0.075" rpy="0.0 0.0 0.0" />
            <geometry>
                <box size="0.15 0.12 0.20" />
            </geometry>
            <!-- Cambiado a naranja -->
            <material name="color_1">
                <color rgba="1.0 0.5 0.0 1.0" /> <!-- Naranja -->
            </material>
        </visual>

        <collision>
            <origin xyz="0.0 0.0 0.075" rpy="0.0 0.0 0.0" />
            <geometry>
                <box size="0.15 0.12 0.20" />
            </geometry>
        </collision>

        <inertial>
            <mass value="1.0" />
            <origin xyz="0.0 0.0 0.0" rpy="0.0 0.0 0.0" />
            <inertia ixx="1.0" ixy="0.0" ixz="0.0" iyy="1.0" iyz="0.0" izz="1.0" />
        </inertial>
    </link>

    <link name="link_1">
        <visual>
            <origin xyz="0.020 0.0 0.25" rpy="0.0 0.0 0.0" />
            <geometry>
                <box size="0.1 0.1 0.5" />
            </geometry>
            <!-- Cambiado a café -->
            <material name="color_2">
                <color rgba="0.6 0.3 0.0 1.0" /> <!-- Café -->
            </material>
        </visual>

        <collision>
            <origin xyz="0.020 0.0 0.25" rpy="0.0 0.0 0.0" />
            <geometry>
                <box size="0.1 0.1 0.5" />
            </geometry>
        </collision>

        <inertial>
            <mass value="1.0" />
            <origin xyz="0.0 0.0 0.0" rpy="0.0 0.0 0.0" />
            <inertia ixx="1.0" ixy="0.0" ixz="0.0" iyy="1.0" iyz="0.0" izz="1.0" />
        </inertial>
    </link>

    <link name="link_2">
        <visual>
            <origin xyz="0.0 0.0 0.15" rpy="0.0 0.0 0.0" />
            <geometry>
                <cylinder radius="0.05" length="0.4" />
            </geometry>
            <!-- Cambiado a rojo -->
            <material name="color_3">
                <color rgba="1.0 0.0 0.0 1.0" /> <!-- Rojo -->
            </material>
        </visual>

        <collision>
            <origin xyz="0.0 0.0 0.15" rpy="0.0 0.0 0.0" />
            <geometry>
                <cylinder radius="0.05" length="0.4" />
            </geometry>
        </collision>

        <inertial>
            <mass value="1.0" />
            <origin xyz="0.0 0.0 0.0" rpy="0.0 0.0 0.0" />
            <inertia ixx="1.0" ixy="0.0" ixz="0.0" iyy="1.0" iyz="0.0" izz="1.0" />
        </inertial>
    </link>

    <joint name="base_link_to_link_1_joint" type="revolute">
        <parent link="base_link" />
        <child link="link_1" />
        <axis xyz="1 0 0" />
        <limit lower="-3.14159" upper="3.14159" velocity="50.0" effort="1000" />
        <origin xyz="0.0 0.0 0.15" rpy="0 0 0" />
    </joint>

    <joint name="link_1_to_link_2_joint" type="revolute">
        <parent link="link_1" />
        <child link="link_2" />
        <axis xyz="1 0 0" />
        <limit lower="-1.5708" upper="1.5708" velocity="50.0" effort="1000" />
        <origin xyz="0.0 0.0 0.5" rpy="0 0 0" />
    </joint>

</robot>